Workbook

Sheet ICMS
B1: Série histórica da receita de ICMS por setor do modelo - em R$$ | C1: 2023
B2: Setor | C2: =SUM(C3:C128) -> 51281981987
A3: ArrozTriCer | B3: Arroz, trigo e outros cereais | C3: 15498612 | E3: Agropec | F3: =SUM(C3:C17) -> 443411827 | G3: Agropec | H3: 443411827
A4: MilhoGrao | B4: Milho em grão | C4: - | E4: Extrativa | F4: {=SUM(C18:C22)} -> 1712736919 | G4: Extrativa | H4: 1712736919
A5: AlgFibTemp | B5: Algodão herbáceo e outras fibras | C5: 85136 | E5: Industria | F5: {=SUM(C23:C89)} -> 24231303195 | G5: Industria | H5: 24231303195
A6: Canadeacu | B6: Cana-de-açúcar | C6: 23840641 | E6: Serviços | F6: {=SUM(C91:C94,C97:C128)} -> 2648366477 | G6: Serviços | H6: 2648366477
A7: SojaGrao | B7: Soja em grão | C7: 6167109 | E7: FabmE | G7: ComAtacVar | H7: 16495663209
A8: OutTempor | B8: Outros produtos da lavoura temporária | C8: 211306088 | E8: Energ | F8: =C90 -> 4934225117 | G8: TranspCarga | H8: 816275243
A9: Laranja | B9: Laranja | C9: 47813139 | E9: ComAtacVar | F9: =C95 -> 16495663209
A10: CafeGrao | B10: Café em grão | C10: 3000389 | E10: TranspCarga | F10: =C96 -> 816275243
A11: OutPerman | B11: Outros produtos da lavoura permanente | C11: 1716542
A12: BovOutAni | B12: Bovinos e outros animais vivos | C12: 15469767
A13: LeiteVacOut | B13: Leite | C13: -
A14: Suinos | B14: Suínos | C14: 3460625
A15: AvesOvos | B15: Aves e ovos | C15: 15960381
A16: ProdExplSilv | B16: Exploração florestal e da silvicultura | C16: 97665517
A17: PescAgric | B17: Pesca e aquicultura | C17: 1427881
A18: CarvMinera | B18: Carvão mineral | C18: 47209
A19: MinerNMet | B19: Minerais não metálicos | C19: 83231234
A20: PetrGasServ | B20: Petróleo e gás natural | C20: 14358
A21: MinerFerro | B21: Minério de ferro | C21: 1488187729
A22: MinMetNFer | B22: Minerais metálicos não ferrosos | C22: 141256389
A23: CarneBoiOut | B23: Carne de bovinos | C23: 142069983
A24: CarneSuino | B24: Carne de suíno | C24: 119108937
A25: CarneAves | B25: Carne de aves | C25: -
A26: PescIndus | B26: Pescado industrializado | C26: 3862415
A27: LeiteResPas | B27: Leite beneficiado | C27: 122606586
A28: OutrLaticin | B28: Outros produtos do laticínio | C28: 601490873
A29: Acucar | B29: Açúcar | C29: 77090332
A30: ConsFruLeg | B30: Conservas e sucos | C30: 188863767
A31: OleoGord | B31: Óleos e gorduras vegetais e animais | C31: 154300649
A32: CafeBenef | B32: Café beneficiado | C32: 110116039
A33: ArrozBenef | B33: Arroz beneficiado | C33: 4712393
A34: ProdTrigMan | B34: Derivados do trigo, mandioca ou milho | C34: 58921309
A35: RacoesAnim | B35: Rações para animais | C35: 202781509
A36: OutrAlimen | B36: Outros produtos alimentares | C36: 688929149
A37: Bebidas | B37: Bebidas | C37: 1612483908
... A47: SerImpres | B47: Impressão e reprodução | C47: 22878730
A48: CombAviac | B48: Combustíveis para aviação | C48: -
A49: Gasoalcool | B49: Gasoálcool | C49: -
...

Sheet xtot
A1: xtot | B1: 1 Aimores | C1: 2 Alfenas | D1: 3 Almenara | E1: 4 Andrelandia | F1: 5 Aracuai | G1: 6 Araxa | H1: 7 Barbacena | I1: 8 BeloHzte | J1: 9 Bocaiuva | K1: 10 BomDespacho | L1: 11 CampoBelo | M1: 12 Capelinha | N1: 13 Caratinga | O1: 14 Cataguases | P1: 15 ConcMatoDen | Q1: 16 Lafaiete | R1: 17 Curvelo | S1: 18 Diamantina | T1: 19 Divinopolis | U1: 20 Formiga | V1: 21 Frutal | W1: 22 GovValad | X1: 23 GraoMogol | Y1: 24 Guanhaes | Z1: 25 Ipatinga | AA1: 26 Itabira | AB1: 27 Itaguara | AC1: 28 Itajuba | AD1: 29 Ituiutaba | AE1: 30 Janauba | AF1: 31 Januaria | AG1: 32 JuizFora | AH1: 33 Lavras | AI1: 34 Manhuau | AJ1: 35 Mantena | AK1: 36 MontesClaros | AL1: 37 Muriae | AM1: 38 Nanuque | AN1: 39 Oliveira | AO1: 40 OuroPreto | AP1: 41 ParaMinas | AQ1: 42 Paracatu | AR1: 43 Passos | AS1: 44 PatosMinas | AT1: 45 Patrocinio | AU1: 46 Pecanha | AV1: 47 PedraAzul | AW1: 48 Pirapora | AX1: 49 Piui | AY1: 50 PocosCaldas | AZ1: 51 PonteNova | BA1: 52 PousoAlegre | BB1: 53 Salinas | BC1: 54 StaRitaSapuc | BD1: 55 SaoJoaoDRei | BE1: 56 SaoLoureno | BF1: 57 SaoSebParai | BG1: 58 SeteLagoas | BH1: 59 TeofOtoni | BI1: 60 TresMarias | BJ1: 61 Uba | BK1: 62 Uberaba | BL1: 63 Uberlandia | BM1: 64 Unai | BN1: 65 Varginha | BO1: 66 Vicosa
A2: 1 Agropec | B2: 1.478 | C2: 5.559 | D2: 8.028 | E2: 2.878 | F2: 6.849 | G2: 2.945 | H2: 2.79 | I2: 2.298 | J2: 8.745 | K2: 6.363 | L2: 3.652 | M2: 4.539 | N2: 6.802 | O2: 4.704 | P2: 1.861 | Q2: 7.91 | R2: 5.779 | S2: 7.269 | T2: 7.307 | U2: 5.568 | V2: 0.864 | W2: 4.006 | X2: 3.338 | Y2: 3.377 | Z2: 3.802 | AA2: 2.315 | AB2: 6.594 | AC2: 3.708 | AD2: 2.655 | AE2: 6.645 | AF2: 10.373 | AG2: 3.728 | AH2: 3.468 | AI2: 4.092 | AJ2: 8.975 | AK2: 5.143 | AL2: 6.727 | AM2: 2.261 | AN2: 6.854 | AO2: 1.053 | AP2: 3.325 | AQ2: 3.993 | AR2: 5.457 | AS2: 3.436 | AT2: 3.52 | AU2: 7.073 | AV2: 12.037 | AW2: 7.347 | AX2: 1.877 | AY2: 2.923 | AZ2: 2.954 | BA2: 4.213 | BB2: 5.478 | BC2: 3.372 | BD2: 5.974 | BE2: 6.08 | BF2: 4.043 | BG2: 6.018 | BH2: 7.689 | BI2: 4.954 | BJ2: 5.091 | BK2: 5.862 | BL2: 1.915 | BM2: 2.646 | BN2: 6.179 | BO2: 5.855
A3: 2 Extrativa | B3: 11.425 | C3: 12.16 | D3: 8.271 | E3: 4.055 | F3: 10.481 | G3: 7.71 | H3: 7.044 | I3: 6.257 | J3: 8.885 | K3: 7.384 | L3: 7.525 | M3: 9.406 | N3: 7.092 | O3: 7.461 | P3: 5.44 | Q3: 6.123 | R3: 7.048 | S3: 7.836 | T3: 6.884 | U3: 5.663 | V3: 3.93 | W3: 8.055 | X3: 5.621 | Y3: 6.39 | Z3: 6.083 | AA3: 5.852 | AB3: 5.99 | AC3: 6.747 | AD3: 6.565 | AE3: 14.904 | AF3: 11.326 | AG3: 6.1 | AH3: 6.409 | AI3: 6.56 | AJ3: 6.156 | AK3: 5.229 | AL3: 10.047 | AM3: 7.132 | AN3: 5.489 | AO3: 5.569 | AP3: 7.245 | AQ3: 7.361 | AR3: 6.988 | AS3: 5.59 | AT3: 7.686 | AU3: 7.396 | AV3: 8.634 | AW3: 8.997 | AX3: 3.684 | AY3: 6.848 | AZ3: 6.81 | BA3: 6.494 | BB3: 13.194 | BC3: 5.827 | BD3: 11.129 | BE3: 5.718 | BF3: 10.875 | BG3: 5.526 | BH3: 6.241 | BI3: 9.242 | BJ3: 5.815 | BK3: 7.172 | BL3: 6.259 | BM3: 8.695 | BN3: 7.242 | BO3: 7.609
A4: 3 Industria | B4: 8.558 | C4: 8.8 | D4: 6.983 | E4: 1.085 | F4: 7.784 | G4: 5.379 | H4: 9.414 | I4: 2.938 | J4: 12.514 | K4: 8.68 | L4: 6.308 | M4: 14.969 | N4: 11.614 | O4: 5.892 | P4: 4.329 | Q4: 7.265 | R4: 9.324 | S4: 8.057 | T4: 10.253 | U4: 5.933 | V4: 0.775 | W4: 11.958 | X4: 5.168 | Y4: 7.001 | Z4: 6.317 | AA4: 5.679 | AB4: 7.292 | AC4: 1.634 | AD4: 7.83 | AE4: 15.347 | AF4: 16.634 | AG4: 7.728 | AH4: 3.653 | AI4: 6.576 | AJ4: 7.79 | AK4: 2.14 | AL4: 8.039 | AM4: 3.129 | AN4: 9.506 | AO4: 4.462 | AP4: 12.341 | AQ4: 1.924 | AR4: 7.001 | AS4: 6.59 | AT4: 9.268 | AU4: 8.695 | AV4: 9.587 | AW4: 10.283 | AX4: 4.573 | AY4: 8.536 | AZ4: 8.386 | BA4: 3.103 | BB4: 11.014 | BC4: -0.886 | BD4: 8.213 | BE4: 4.722 | BF4: 6.502 | BG4: 4.488 | BH4: 10.521 | BI4: 10.953 | BJ4: 4.741 | BK4: 3.812 | BL4: 3.05 | BM4: 7.164 | BN4: 4.878 | BO4: 7.32
A5: 6 Servico | B5: 6.157 | C5: 1.89 | D5: 5.692 | E5: 8.306 | F5: 7.17 | G5: 3.676 | H5: 2.776 | I5: 2.153 | J5: 10.97 | K5: 6.186 | L5: 7.688 | M5: 5.98 | N5: 2.339 | O5: 3.117 | P5: 2.347 | Q5: 2.525 | R5: 9.799 | S5: 4.05 | T5: 5.419 | U5: 8.716 | V5: 5.164 | W5: 2.304 | X5: 5.657 | Y5: 3.833 | Z5: 3.511 | AA5: 4.18 | AB5: 5.239 | AC5: 2.777 | AD5: 3.729 | AE5: 3.278 | AF5: 2.734 | AG5: 0.821 | AH5: 5.439 | AI5: 2.803 | AJ5: 2.675 | AK5: 9.143 | AL5: 4.05 | AM5: 1.36 | AN5: 3.04 | AO5: 3.294 | AP5: 2.669 | AQ5: 13.606 | AR5: 4.29 | AS5: 4.926 | AT5: 5.069 | AU5: 0.848 | AV5: 1.907 | AW5: 12.528 | AX5: 13.892 | AY5: 3.286 | AZ5: 4.12 | BA5: 1.165 | BB5: 14.605 | BC5: 4.114 | BD5: 0.752 | BE5: 4.254 | BF5: 3.563 | BG5: 8.273 | BH5: 5.274 | BI5: 4.028 | BJ5: 3.81 | BK5: 1.619 | BL5: 2.211 | BM5: 2.418 | BN5: 4.075 | BO5: 1.918
A6: 7 ComAtaVar | B6: 7.107 | C6: 7.385 | D6: 8.774 | E6: 4.643 | F6: 6.015 | G6: 6.277 | H6: 5.868 | I6: 5.74 | J6: 12.13 | K6: 9.092 | L6: 6.93 | M6: 11.097 | N6: 9.46 | O6: 6.751 | P6: 5.361 | Q6: 5.978 | R6: 9.213 | S6: 9.475 | T6: 9.206 | U6: 7.728 | V6: 18.766 | W6: 8.614 | X6: 8.247 | Y6: 7.096 | Z6: 7.041 | AA6: 6.539 | AB6: 7.141 | AC6: 4.912 | AD6: 6.61 | AE6: 9.819 | AF6: 14.436 | AG6: 5.755 | AH6: 5.911 | AI6: 7.656 | AJ6: 9.726 | AK6: 7.828 | AL6: 6.32 | AM6: 5.505 | AN6: 7.613 | AO6: 4.915 | AP6: 8.557 | AQ6: 6.021 | AR6: 7.675 | AS6: 7.494 | AT6: 7.529 | AU6: 9.098 | AV6: 6.445 | AW6: 11.376 | AX6: 7.521 | AY6: 6.973 | AZ6: 6.803 | BA6: 4.822 | BB6: 12.709 | BC6: 5.253 | BD6: 6.655 | BE6: 5.907 | BF6: 7.866 | BG6: 7.726 | BH6: 7.843 | BI6: 10.293 | BJ6: 7.55 | BK6: 7.049 | BL6: 4.552 | BM6: 7.076 | BN6: 7.314 | BO6: 7.696
A7: 8 TranspCarga | B7: 1.707 | C7: 4.157 | D7: 0.372 | E7: -1.318 | F7: 2.129 | G7: 1.522 | H7: 3.073 | I7: 2.786 | J7: 0.776 | K7: 1.822 | L7: -0.153 | M7: 2.468 | N7: 5.721 | O7: 1.151 | P7: 0.32 | Q7: 2.961 | R7: 0.416 | S7: 1.278 | T7: 3.765 | U7: 1.82 | V7: -0.463 | W7: 4.081 | X7: 4.431 | Y7: 2.321 | Z7: 3.399 | AA7: 3.387 | AB7: 0.126 | AC7: 1.666 | AD7: 1.634 | AE7: 5.533 | AF7: 6.363 | AG7: 2.689 | AH7: 1.821 | AI7: 4.264 | AJ7: 2.607 | AK7: 1.952 | AL7: 2.609 | AM7: 1.316 | AN7: 2.408 | AO7: 2.13 | AP7: 3.78 | AQ7: -0.253 | AR7: 2.154 | AS7: 2.359 | AT7: 2.557 | AU7: 0.931 | AV7: 2.36 | AW7: 3.473 | AX7: -3.35 | AY7: 1.365 | AZ7: 2.065 | BA7: 1.908 | BB7: 1.386 | BC7: 1.668 | BD7: 4.114 | BE7: 0.775 | BF7: 1.149 | BG7: 3.074 | BH7: 2.52 | BI7: 3.08 | BJ7: 2.401 | BK7: 3.569 | BL7: 2.413 | BM7: 2.705 | BN7: 2.527 | BO7: 5.085

Sheet Make
A1: MAKE | B1: 1 Aimores | C1: 2 Alfenas | D1: 3 Almenara | E1: 4 Andrelandia | F1: 5 Aracuai | G1: 6 Araxa | H1: 7 Barbacena | I1: 8 BeloHzte | J1: 9 Bocaiuva | K1: 10 BomDespacho | L1: 11 CampoBelo | M1: 12 Capelinha | N1: 13 Caratinga | O1: 14 Cataguases | P1: 15 ConcMatoDen | Q1: 16 Lafaiete | R1: 17 Curvelo | S1: 18 Diamantina | T1: 19 Divinopolis | U1: 20 Formiga | V1: 21 Frutal | W1: 22 GovValad | X1: 23 GraoMogol | Y1: 24 Guanhaes | Z1: 25 Ipatinga | AA1: 26 Itabira | AB1: 27 Itaguara | AC1: 28 Itajuba | AD1: 29 Ituiutaba | AE1: 30 Janauba | AF1: 31 Januaria | AG1: 32 JuizFora | AH1: 33 Lavras | AI1: 34 Manhuau | AJ1: 35 Mantena | AK1: 36 MontesClaros | AL1: 37 Muriae | AM1: 38 Nanuque | AN1: 39 Oliveira | AO1: 40 OuroPreto | AP1: 41 ParaMinas | AQ1: 42 Paracatu | AR1: 43 Passos | AS1: 44 PatosMinas | AT1: 45 Patrocinio | AU1: 46 Pecanha | AV1: 47 PedraAzul | AW1: 48 Pirapora | AX1: 49 Piui | AY1: 50 PocosCaldas | AZ1: 51 PonteNova | BA1: 52 PousoAlegre | BB1: 53 Salinas | BC1: 54 StaRitaSapuc | BD1: 55 SaoJoaoDRei | BE1: 56 SaoLoureno | BF1: 57 SaoSebParai | BG1: 58 SeteLagoas | BH1: 59 TeofOtoni | BI1: 60 TresMarias | BJ1: 61 Uba | BK1: 62 Uberaba | BL1: 63 Uberlandia | BM1: 64 Unai | BN1: 65 Varginha | BO1: 66 Vicosa | BP1: Total
A2: 1 Agropec | B2: 1020.46 | C2: 1380.387 | D2: 261.808 | E2: 463.809 | F2: 198.477 | G2: 3772.72 | H2: 912.596 | I2: 5115.417 | J2: 188.117 | K2: 959.835 | L2: 527.138 | M2: 695.792 | N2: 728.935 | O2: 528.432 | P2: 338.241 | Q2: 258.586 | R2: 553.889 | S2: 179.491 | T2: 1023.221 | U2: 675.281 | V2: 2466.427 | W2: 1259.672 | X2: 72.06 | Y2: 421.634 | Z2: 481.718 | AA2: 988.848 | AB2: 301.986 | AC2: 567.935 | AD2: 1359.478 | AE2: 767.769 | AF2: 554.21 | AG2: 976.474 | AH2: 685.425 | AI2: 1430.203 | AJ2: 156.865 | AK2: 859.228 | AL2: 833.851 | AM2: 985.499 | AN2: 616.995 | AO2: 481.845 | AP2: 1134.106 | AQ2: 3003.09 | AR2: 1445.273 | AS2: 2307.646 | AT2: 2738.116 | AU2: 258.204 | AV2: 64.028 | AW2: 426.117 | AX2: 977.355 | AY2: 1532.765 | AZ2: 1297.959 | BA2: 784.204 | BB2: 303.682 | BC2: 689.081 | BD2: 668.336 | BE2: 895.664 | BF2: 1525.949 | BG2: 1181.746 | BH2: 612.708 | BI2: 710.973 | BJ2: 815.037 | BK2: 1959.907 | BL2: 6903.36 | BM2: 4158.187 | BN2: 2031.981 | BO2: 904.795 | BP2: {=SUM(B2:BO2)} -> 75381.023
A3: 2 Extrativa | B3: 14.285 | C3: 42.517 | D3: 8.082 | E3: 7.168 | F3: 6.764 | G3: 274.055 | H3: 41.501 | I3: 11865.494 | J3: 10.287 | K3: 44.567 | L3: 16.362 | M3: 9.472 | N3: 17.669 | O3: 102.114 | P3: 183.419 | Q3: 1193.952 | R3: 14.951 | S3: 8.154 | T3: 555.367 | U3: 66.438 | V3: 163.709 | W3: 52.067 | X3: 13.475 | Y3: 17.114 | Z3: 1024.349 | AA3: 1678.995 | AB3: 304.317 | AC3: 64.942 | AD3: 51.565 | AE3: 52.112 | AF3: 8.587 | AG3: 284.77 | AH3: 40.027 | AI3: 130.4 | AJ3: 3.805 | AK3: 117.553 | AL3: 69.993 | AM3: 14.212 | AN3: 80.276 | AO3: 2040.566 | AP3: 45.371 | AQ3: 256.374 | AR3: 124.874 | AS3: 56.618 | AT3: 36.362 | AU3: 2.3 | AV3: 6.187 | AW3: 27.695 | AX3: 23.228 | AY3: 257.922 | AZ3: 26.919 | BA3: 237.989 | BB3: 12.357 | BC3: 48.545 | BD3: 72.835 | BE3: 39.859 | BF3: 67.309 | BG3: 222.529 | BH3: 21.065 | BI3: 60.743 | BJ3: 109.861 | BK3: 290.425 | BL3: 653.87 | BM3: 35.823 | BN3: 122.178 | BO3: 17.599 | BP3: {=SUM(B3:BO3)} -> 23572.289
A4: 3 Industria | B4: 128.811 | C4: 910.801 | D4: 204.38 | E4: 94.82 | F4: 132.493 | G4: 6960.552 | H4: 893.533 | I4: 73653.414 | J4: 1674.594 | K4: 731.042 | L4: 292.3 | M4: 237.751 | N4: 349.461 | O4: 1021.153 | P4: 489.684 | Q4: 8122.396 | R4: 313.678 | S4: 129.142 | T4: 3840.468 | U4: 1575.124 | V4: 2014.759 | W4: 691.227 | X4: 258.749 | Y4: 344.682 | Z4: 12391.322 | AA4: 10034.666 | AB4: 1978.367 | AC4: 1341.667 | AD4: 899.987 | AE4: 456.53 | AF4: 226.772 | AG4: 8075.483 | AH4: 713.482 | AI4: 1545.91 | AJ4: 61.498 | AK4: 7299.569 | AL4: 512.418 | AM4: 167.127 | AN4: 348.182 | AO4: 11223.342 | AP4: 703.823 | AQ4: 3441.248 | AR4: 1761.126 | AS4: 1338.517 | AT4: 668.127 | AU4: 25.548 | AV4: 100.841 | AW4: 1931.204 | AX4: 618.186 | AY4: 2814.291 | AZ4: 242.56 | BA4: 5104.841 | BB4: 500.349 | BC4: 1192.686 | BD4: 820.233 | BE4: 883.625 | BF4: 1211.865 | BG4: 6828.63 | BH4: 361.747 | BI4: 7024.139 | BJ4: 2091.818 | BK4: 9163.846 | BL4: 19623.193 | BM4: 671.462 | BN4: 3164.433 | BO4: 332.122 | BP4: {=SUM(B4:BO4)} -> 234961.8
A5: 4 FabMEletr | B5: 0.973 | C5: 29.949 | D5: 0.022 | E5: 0.015 | F5: 0.015 | G5: 9.223 | H5: 1.233 | I5: 5049.676 | J5: 0.02 | K5: 1.119 | L5: 1.173 | M5: 4.25 | N5: 0.616 | O5: 0.149 | P5: 0.023 | Q5: 2.728 | R5: 0.757 | S5: 6.837 | T5: 40.537 | U5: 1.313 | V5: 0.672 | W5: 97.823 | X5: 0.005 | Y5: 0.024 | Z5: 0.977 | AA5: 5.291 | AB5: 23.774 | AC5: 97.604 | AD5: 0.065 | AE5: 0.039 | AF5: 0.044 | AG5: 12.687 | AH5: 5.437 | AI5: 16.341 | AJ5: 0.073 | AK5: 1.47 | AL5: 2.946 | AM5: 0.034 | AN5: 0.114 | AO5: 0.201 | AP5: 11.201 | AQ5: 0.117 | AR5: 6.919 | AS5: 14.215 | AT5: 4.348 | AU5: 0.01 | AV5: 0.684 | AW5: 0.046 | AX5: 0.037 | AY5: 182.75 | AZ5: 0.045 | BA5: 336.417 | BB5: 0.029 | BC5: 281.994 | BD5: 3.212 | BE5: 1.554 | BF5: 218.445 | BG5: 25.612 | BH5: 0.055 | BI5: 1.677 | BJ5: 4.884 | BK5: 374.751 | BL5: 155.529 | BM5: 4.92 | BN5: 248.031 | BO5: 1.526 | BP5: {=SUM(B5:BO5)} -> 7295.257
A6: 5 EnergGas | B6: 49.931 | C6: 7.203 | D6: 0.051 | E6: 0.034 | F6: 0.033 | G6: 253.412 | H6: 147.126 | I6: 9260.431 | J6: 0.046 | K6: 4.372 | L6: 13.375 | M6: 0.067 | N6: 28.813 | O6: 324.39 | P6: 0.052 | Q6: 0.364 | R6: 72.787 | S6: 0.042 | T6: 169.486 | U6: 0.146 | V6: 969.268 | W6: 6.432 | X6: 0.011 | Y6: 0.054 | Z6: 135.307 | AA6: 0.499 | AB6: 3.601 | AC6: 13.123 | AD6: 66.41 | AE6: 0.089 | AF6: 0.101 | AG6: 232.549 | AH6: 43.984 | AI6: 2.573 | AJ6: 0.024 | AK6: 0.439 | AL6: 0.166 | AM6: 0.077 | AN6: 3.601 | AO6: 483.056 | AP6: 0.139 | AQ6: 392.449 | AR6: 418.806 | AS6: 0.278 | AT6: 1.801 | AU6: 0.023 | AV6: 0.03 | AW6: 0.105 | AX6: 27.78 | AY6: 471.428 | AZ6: 22.379 | BA6: 558.79 | BB6: 0.067 | BC6: 0.124 | BD6: 0.161 | BE6: 36.794 | BF6: 55.313 | BG6: 24.946 | BH6: 0.124 | BI6: 0.158 | BJ6: 0.213 | BK6: 77.965 | BL6: 905.022 | BM6: 10.553 | BN6: 1.029 | BO6: 0.124 | BP6: {=SUM(B6:BO6)} -> 15300.126
A7: 6 Servico | B7: 1126.985 | C7: 4342.864 | D7: 1109.041 | E7: 562.014 | F7: 717.94 | G7: 6987.077 | H7: 3011.011 | I7: 144044.98 | J7: 557.718 | K7: 2995.806 | L7: 1301.076 | M7: 1169.052 | N7: 2374.986 | O7: 3432.745 | P7: 1004.518 | Q7: 6506.674 | R7: 1881.252 | S7: 904.353 | T7: 10186.54 | U7: 2745.245 | V7: 4279.482 | W7: 6567.197 | X7: 109.022 | Y7: 1121.91 | Z7: 12159.876 | AA7: 9195.982 | AB7: 1370.741 | AC7: 3221.52 | AD7: 2979.021 | AE7: 1866.389 | AF7: 2110.114 | AG7: 16464.967 | AH7: 2852.262 | AI7: 3574.189 | AJ7: 494.458 | AK7: 8528.331 | AL7: 3644.684 | AM7: 1518.384 | AN7: 1598.368 | AO7: 7218.215 | AP7: 2830.813 | AQ7: 4148.648 | AR7: 3823.11 | AS7: 5356.05 | AT7: 4090.446 | AU7: 417.529 | AV7: 707.108 | AW7: 1780.471 | AX7: 1516.575 | AY7: 7878.911 | AZ7: 1982.265 | BA7: 13925.152 | BB7: 1359.169 | BC7: 2431.673 | BD7: 3239.74 | BE7: 2969.37 | BF7: 5391.696 | BG7: 8675.742 | BH7: 2733.765 | BI7: 1930.224 | BJ7: 4099.826 | BK7: 12501.188 | BL7: 31129.326 | BM7: 2888.16 | BN7: 8757.1 | BO7: 2517.306 | BP7: {=SUM(B7:BO7)} -> 426918.36
A8: 7 ComAtaVar | B8: 235.4 | C8: 784.737 | D8: 186.699 | E8: 127.522 | F8: 149.33 | G8: 1104.044 | H8: 594.938 | I8: 29011.592 | J8: 104.694 | K8: 601.122 | L8: 270.521 | M8: 231.229 | N8: 440.564 | O8: 649.94 | P8: 148.235 | Q8: 968.016 | R8: 337.876 | S8: 162.745 | T8: 1838.555 | U8: 500.6 | V8: 643.97 | W8: 1220.129 | X8: 26.96 | Y8: 213.533 | Z8: 2015.06 | AA8: 1365.125 | AB8: 193.802 | AC8: 567.135 | AD8: 584.916 | AE8: 350.488 | AF8: 272.752 | AG8: 3068.262 | AH8: 497.513 | AI8: 692.451 | AJ8: 95.401 | AK8: 1655.47 | AL8: 695.554 | AM8: 200.185 | AN8: 310.92 | AO8: 1025.09 | AP8: 460.366 | AQ8: 703.683 | AR8: 697.631 | AS8: 1021.103 | AT8: 773.362 | AU8: 69.456 | AV8: 129.633 | AW8: 330.711 | AX8: 270.531 | AY8: 1580.158 | AZ8: 405.287 | BA8: 2437.178 | BB8: 264.421 | BC8: 455.11 | BD8: 487.15 | BE8: 582.653 | BF8: 1024.217 | BG8: 1393.897 | BH8: 537.097 | BI8: 275.731 | BJ8: 686.224 | BK8: 2074.617 | BL8: 5410.246 | BM8: 496.743 | BN8: 1746.621 | BO8: 431.188 | BP8: {=SUM(B8:BO8)} -> 78888.089
A9: 8 TranspCarga | B9: 73.606 | C9: 216.171 | D9: 16.781 | E9: 37.538 | F9: 33.299 | G9: 367.554 | H9: 134.317 | I9: 6888.385 | J9: 48.782 | K9: 332.128 | L9: 150.325 | M9: 105.633 | N9: 66.8 | O9: 286.199 | P9: 8.506 | Q9: 314.873 | R9: 99.791 | S9: 21.265 | T9: 581.196 | U9: 260.361 | V9: 335.225 | W9: 349.278 | X9: 2.253 | Y9: 86.307 | Z9: 763.984 | AA9: 438.518 | AB9: 95.529 | AC9: 139.403 | AD9: 128.705 | AE9: 82.11 | AF9: 24.038 | AG9: 1252.592 | AH9: 263.634 | AI9: 176.628 | AJ9: 16.272 | AK9: 345.005 | AL9: 235.916 | AM9: 40.074 | AN9: 126.795 | AO9: 320.667 | AP9: 240.035 | AQ9: 271.824 | AR9: 247.177 | AS9: 425.595 | AT9: 277.488 | AU9: 3.503 | AV9: 43.317 | AW9: 93.836 | AX9: 69.289 | AY9: 616.969 | AZ9: 131.08 | BA9: 763.374 | BB9: 103.388 | BC9: 140.125 | BD9: 101.803 | BE9: 198.696 | BF9: 391.321 | BG9: 503.389 | BH9: 206.747 | BI9: 62.042 | BJ9: 351.497 | BK9: 692.233 | BL9: 1877.416 | BM9: 211.82 | BN9: 491.827 | BO9: 74.041 | BP9: {=SUM(B9:BO9)} -> 23856.275
A10: TOTAL | B10: {=SUM(B2:B9)} -> 2650.451 | C10: {=SUM(C2:C9)} -> 7714.629 | D10: {=SUM(D2:D9)} -> 1786.864 | E10: {=SUM(E2:E9)} -> 1292.92 | F10: {=SUM(F2:F9)} -> 1238.351 | G10: {=SUM(G2:G9)} -> 19728.637 | H10: {=SUM(H2:H9)} -> 5736.255 | I10: {=SUM(I2:I9)} -> 284889.39 | ... BO10: {=SUM(BO2:BO9)} -> 4278.701

Sheet Share_Make 
A1: MAKE | B1: 1 Aimores | C1: 2 Alfenas | D1: 3 Almenara | E1: 4 Andrelandia | F1: 5 Aracuai | G1: 6 Araxa | H1: 7 Barbacena | I1: 8 BeloHzte | J1: 9 Bocaiuva | K1: 10 BomDespacho | L1: 11 CampoBelo | M1: 12 Capelinha | N1: 13 Caratinga | O1: 14 Cataguases | P1: 15 ConcMatoDen | Q1: 16 Lafaiete | R1: 17 Curvelo | S1: 18 Diamantina | T1: 19 Divinopolis | U1: 20 Formiga | V1: 21 Frutal | W1: 22 GovValad | X1: 23 GraoMogol | Y1: 24 Guanhaes | Z1: 25 Ipatinga | AA1: 26 Itabira | AB1: 27 Itaguara | AC1: 28 Itajuba | AD1: 29 Ituiutaba | AE1: 30 Janauba | AF1: 31 Januaria | AG1: 32 JuizFora | AH1: 33 Lavras | AI1: 34 Manhuau | AJ1: 35 Mantena | AK1: 36 MontesClaros | AL1: 37 Muriae | AM1: 38 Nanuque | AN1: 39 Oliveira | AO1: 40 OuroPreto | AP1: 41 ParaMinas | AQ1: 42 Paracatu | AR1: 43 Passos | AS1: 44 PatosMinas | AT1: 45 Patrocinio | AU1: 46 Pecanha | AV1: 47 PedraAzul | AW1: 48 Pirapora | AX1: 49 Piui | AY1: 50 PocosCaldas | AZ1: 51 PonteNova | BA1: 52 PousoAlegre | BB1: 53 Salinas | BC1: 54 StaRitaSapuc | BD1: 55 SaoJoaoDRei | BE1: 56 SaoLoureno | BF1: 57 SaoSebParai | BG1: 58 SeteLagoas | BH1: 59 TeofOtoni | BI1: 60 TresMarias | BJ1: 61 Uba | BK1: 62 Uberaba | BL1: 63 Uberlandia | BM1: 64 Unai | BN1: 65 Varginha | BO1: 66 Vicosa | BP1: Total
A2: 1 Agropec | B2: =Make!B2/Make!$BP2 -> 0.013537359 | C2: =Make!C2/Make!$BP2 -> 0.018312129 | D2: =Make!D2/Make!$BP2 -> 0.0034731288 | E2: =Make!E2/Make!$BP2 -> 0.0061528616 | F2: =Make!F2/Make!$BP2 -> 0.0026329836 | G2: =Make!G2/Make!$BP2 -> 0.050048671 | H2: =Make!H2/Make!$BP2 -> 0.012106442 | I2: =Make!I2/Make!$BP2 -> 0.067860806 | ... BO2: =Make!BO2/Make!$BP2 -> 0.012002955 | BP2: {=SUM(B2:BO2)} -> 1
A3: 2 Extrativa | B3: =Make!B3/Make!$BP3 -> 0.00060600818 | C3: =Make!C3/Make!$BP3 -> 0.0018036857 | D3: =Make!D3/Make!$BP3 -> 0.00034286021 | E3: =Make!E3/Make!$BP3 -> 0.00030408587 | F3: =Make!F3/Make!$BP3 -> 0.0002869471 | G3: =Make!G3/Make!$BP3 -> 0.011626151 | H3: =Make!H3/Make!$BP3 -> 0.0017605842 | I3: =Make!I3/Make!$BP3 -> 0.50336622 | ... BO3: =Make!BO3/Make!$BP3 -> 0.00074659699 | BP3: {=SUM(B3:BO3)} -> 1
A4: 3 Industria | B4: =Make!B4/Make!$BP4 -> 0.00054822104 | C4: =Make!C4/Make!$BP4 -> 0.0038763791 | D4: =Make!D4/Make!$BP4 -> 0.00086984354 | E4: =Make!E4/Make!$BP4 -> 0.00040355497 | F4: =Make!F4/Make!$BP4 -> 0.00056389167 | G4: =Make!G4/Make!$BP4 -> 0.029624186 | H4: =Make!H4/Make!$BP4 -> 0.0038028863 | I4: =Make!I4/Make!$BP4 -> 0.31346974 | ... BO4: =Make!BO4/Make!$BP4 -> 0.0014135149 | BP4: {=SUM(B4:BO4)} -> 1
A5: 4 FabMEletr | B5: =Make!B5/Make!$BP5 -> 0.00013337433 | C5: =Make!C5/Make!$BP5 -> 0.00410527 | D5: =Make!D5/Make!$BP5 -> 3.015658e-06 | E5: =Make!E5/Make!$BP5 -> 2.0561304e-06 | F5: =Make!F5/Make!$BP5 -> 2.0561304e-06 | G5: =Make!G5/Make!$BP5 -> 0.0012642461 | H5: =Make!H5/Make!$BP5 -> 0.00016901392 | I5: =Make!I5/Make!$BP5 -> 0.69218617 | ... BO5: =Make!BO5/Make!$BP5 -> 0.000209177 | BP5: {=SUM(B5:BO5)} -> 1
A6: 5 EnergGas | B6: =Make!B6/Make!$BP6 -> 0.0032634372 | C6: =Make!C6/Make!$BP6 -> 0.00047078044 | D6: =Make!D6/Make!$BP6 -> 3.3333059e-06 | E6: =Make!E6/Make!$BP6 -> 2.2222039e-06 | F6: =Make!F6/Make!$BP6 -> 2.156845e-06 | G6: =Make!G6/Make!$BP6 -> 0.016562739 | H6: =Make!H6/Make!$BP6 -> 0.0096159992 | I6: =Make!I6/Make!$BP6 -> 0.60525194 | ... BO6: =Make!BO6/Make!$BP6 -> 8.1045084e-06 | BP6: {=SUM(B6:BO6)} -> 1
A7: 6 Servico | B7: =Make!B7/Make!$BP7 -> 0.0026398139 | C7: =Make!C7/Make!$BP7 -> 0.010172587 | D7: =Make!D7/Make!$BP7 -> 0.0025977824 | E7: =Make!E7/Make!$BP7 -> 0.0013164437 | F7: =Make!F7/Make!$BP7 -> 0.0016816799 | G7: =Make!G7/Make!$BP7 -> 0.016366307 | H7: =Make!H7/Make!$BP7 -> 0.0070528965 | I7: =Make!I7/Make!$BP7 -> 0.3374064 | ... BO7: =Make!BO7/Make!$BP7 -> 0.0058964576 | BP7: {=SUM(B7:BO7)} -> 1
A8: 7 ComAtaVar | B8: =Make!B8/Make!$BP8 -> 0.0029839739 | C8: =Make!C8/Make!$BP8 -> 0.0099474713 | D8: =Make!D8/Make!$BP8 -> 0.002366631 | E8: =Make!E8/Make!$BP8 -> 0.0016164924 | F8: =Make!F8/Make!$BP8 -> 0.0018929347 | G8: =Make!G8/Make!$BP8 -> 0.013995066 | H8: =Make!H8/Make!$BP8 -> 0.0075415441 | I8: =Make!I8/Make!$BP8 -> 0.3677563 | ... BO8: =Make!BO8/Make!$BP8 -> 0.0054658188 | BP8: {=SUM(B8:BO8)} -> 1
A9: 8 TranspCarga | B9: =Make!B9/Make!$BP9 -> 0.0030853937 | C9: =Make!C9/Make!$BP9 -> 0.0090613895 | D9: =Make!D9/Make!$BP9 -> 0.0007034208 | E9: =Make!E9/Make!$BP9 -> 0.0015735063 | F9: =Make!F9/Make!$BP9 -> 0.0013958172 | G9: =Make!G9/Make!$BP9 -> 0.015407016 | H9: =Make!H9/Make!$BP9 -> 0.0056302587 | I9: =Make!I9/Make!$BP9 -> 0.2887452 | ... BO9: =Make!BO9/Make!$BP9 -> 0.0031036279 | BP9: {=SUM(B9:BO9)} -> 1

Sheet ICMS_Micro
A1: MAKE | B1: 1 Aimores | C1: 2 Alfenas | D1: 3 Almenara | E1: 4 Andrelandia | F1: 5 Aracuai | G1: 6 Araxa | H1: 7 Barbacena | I1: 8 BeloHzte | J1: 9 Bocaiuva | K1: 10 BomDespacho | L1: 11 CampoBelo | M1: 12 Capelinha | N1: 13 Caratinga | O1: 14 Cataguases | P1: 15 ConcMatoDen | Q1: 16 Lafaiete | R1: 17 Curvelo | S1: 18 Diamantina | T1: 19 Divinopolis | U1: 20 Formiga | V1: 21 Frutal | W1: 22 GovValad | X1: 23 GraoMogol | Y1: 24 Guanhaes | Z1: 25 Ipatinga | AA1: 26 Itabira | AB1: 27 Itaguara | AC1: 28 Itajuba | AD1: 29 Ituiutaba | AE1: 30 Janauba | AF1: 31 Januaria | AG1: 32 JuizFora | AH1: 33 Lavras | AI1: 34 Manhuau | AJ1: 35 Mantena | AK1: 36 MontesClaros | AL1: 37 Muriae | AM1: 38 Nanuque | AN1: 39 Oliveira | AO1: 40 OuroPreto | AP1: 41 ParaMinas | AQ1: 42 Paracatu | AR1: 43 Passos | AS1: 44 PatosMinas | AT1: 45 Patrocinio | AU1: 46 Pecanha | AV1: 47 PedraAzul | AW1: 48 Pirapora | AX1: 49 Piui | AY1: 50 PocosCaldas | AZ1: 51 PonteNova | BA1: 52 PousoAlegre | BB1: 53 Salinas | BC1: 54 StaRitaSapuc | BD1: 55 SaoJoaoDRei | BE1: 56 SaoLoureno | BF1: 57 SaoSebParai | BG1: 58 SeteLagoas | BH1: 59 TeofOtoni | BI1: 60 TresMarias | BJ1: 61 Uba | BK1: 62 Uberaba | BL1: 63 Uberlandia | BM1: 64 Unai | BN1: 65 Varginha | BO1: 66 Vicosa | BP1: Total
A2: 1 Agropec | B2: =ICMS!$H$3*'Share_Make '!B2 -> 6002625.3 | C2: =ICMS!$H$3*'Share_Make '!C2 -> 8119814.5 | D2: =ICMS!$H$3*'Share_Make '!D2 -> 1540026.4 | E2: =ICMS!$H$3*'Share_Make '!E2 -> 2728251.6 | F2: =ICMS!$H$3*'Share_Make '!F2 -> 1167496.1 | G2: =ICMS!$H$3*'Share_Make '!G2 -> 22192173 | H2: =ICMS!$H$3*'Share_Make '!H2 -> 5368139.7 | I2: =ICMS!$H$3*'Share_Make '!I2 -> 30090284 | ... BO2: =ICMS!$H$3*'Share_Make '!BO2 -> 5322252 | BP2: {=SUM(B2:BO2)} -> 443411827
A3: 2 Extrativa | B3: =ICMS!$H$4*'Share_Make '!B3 -> 1037932.6 | C3: =ICMS!$H$4*'Share_Make '!C3 -> 3089239 | D3: =ICMS!$H$4*'Share_Make '!D3 -> 587229.34 | E3: =ICMS!$H$4*'Share_Make '!E3 -> 520819.1 | F3: =ICMS!$H$4*'Share_Make '!F3 -> 491464.89 | G3: =ICMS!$H$4*'Share_Make '!G3 -> 19912539 | H3: =ICMS!$H$4*'Share_Make '!H3 -> 3015417.6 | I3: =ICMS!$H$4*'Share_Make '!I3 -> 8.6213391e+08 | ... BO3: =ICMS!$H$4*'Share_Make '!BO3 -> 1278724.2 | BP3: {=SUM(B3:BO3)} -> 1.7127369e+09
A4: 3 Industria | B4: =ICMS!$H$5*'Share_Make '!B4 -> 13284110 | C4: =ICMS!$H$5*'Share_Make '!C4 -> 93929718 | D4: =ICMS!$H$5*'Share_Make '!D4 -> 21077443 | E4: =ICMS!$H$5*'Share_Make '!E4 -> 9778662.8 | F4: =ICMS!$H$5*'Share_Make '!F4 -> 13663830 | G4: =ICMS!$H$5*'Share_Make '!G4 -> 7.1783264e+08 | H4: =ICMS!$H$5*'Share_Make '!H4 -> 92148891 | I4: =ICMS!$H$5*'Share_Make '!I4 -> 7.5957804e+09 | ... BO4: =ICMS!$H$5*'Share_Make '!BO4 -> 34251308 | BP4: {=SUM(B4:BO4)} -> 2.4231303e+10
A5: 6 Servico | B5: =ICMS!$H$6*'Share_Make '!B7 -> 6991194.6 | C5: =ICMS!$H$6*'Share_Make '!C7 -> 26940738 | D5: =ICMS!$H$6*'Share_Make '!D7 -> 6879879.9 | E5: =ICMS!$H$6*'Share_Make '!E7 -> 3486425.5 | F5: =ICMS!$H$6*'Share_Make '!F7 -> 4453704.6 | G5: =ICMS!$H$6*'Share_Make '!G7 -> 43343980 | H5: =ICMS!$H$6*'Share_Make '!H7 -> 18678655 | I5: =ICMS!$H$6*'Share_Make '!I7 -> 8.9357579e+08 | ... BO5: =ICMS!$H$6*'Share_Make '!BO7 -> 15615981 | BP5: {=SUM(B5:BO5)} -> 2648366477
A6: 7 ComAtaVar | B6: =ICMS!$H$7*'Share_Make '!B8 -> 49222629 | C6: =ICMS!$H$7*'Share_Make '!C8 -> 1.6409014e+08 | D6: =ICMS!$H$7*'Share_Make '!D8 -> 39039149 | E6: =ICMS!$H$7*'Share_Make '!E8 -> 26665115 | F6: =ICMS!$H$7*'Share_Make '!F8 -> 31225213 | G6: =ICMS!$H$7*'Share_Make '!G8 -> 2.3085789e+08 | H6: =ICMS!$H$7*'Share_Make '!H8 -> 1.2440277e+08 | I6: =ICMS!$H$7*'Share_Make '!I8 -> 6.0663841e+09 | ... BO6: =ICMS!$H$7*'Share_Make '!BO8 -> 90162306 | BP6: {=SUM(B6:BO6)} -> 1.6495663e+10
A7: 8 TranspCarga | B7: =ICMS!$H$8*'Share_Make '!B9 -> 2518530.5 | C7: =ICMS!$H$8*'Share_Make '!C9 -> 7396587.9 | D7: =ICMS!$H$8*'Share_Make '!D9 -> 574184.98 | E7: =ICMS!$H$8*'Share_Make '!E9 -> 1284414.3 | F7: =ICMS!$H$8*'Share_Make '!F9 -> 1139371.1 | G7: =ICMS!$H$8*'Share_Make '!G9 -> 12576365 | H7: =ICMS!$H$8*'Share_Make '!H9 -> 4595840.8 | I7: =ICMS!$H$8*'Share_Make '!I9 -> 2.3569556e+08 | ... BO7: =ICMS!$H$8*'Share_Make '!BO9 -> 2533414.6 | BP7: {=SUM(B7:BO7)} -> 816275243

Sheet Impacto_Imposto
A1: MAKE | B1: 1 Aimores | C1: 2 Alfenas | D1: 3 Almenara | E1: 4 Andrelandia | F1: 5 Aracuai | G1: 6 Araxa | H1: 7 Barbacena | I1: 8 BeloHzte | J1: 9 Bocaiuva | K1: 10 BomDespacho | L1: 11 CampoBelo | M1: 12 Capelinha | N1: 13 Caratinga | O1: 14 Cataguases | P1: 15 ConcMatoDen | Q1: 16 Lafaiete | R1: 17 Curvelo | S1: 18 Diamantina | T1: 19 Divinopolis | U1: 20 Formiga | V1: 21 Frutal | W1: 22 GovValad | X1: 23 GraoMogol | Y1: 24 Guanhaes | Z1: 25 Ipatinga | AA1: 26 Itabira | AB1: 27 Itaguara | AC1: 28 Itajuba | AD1: 29 Ituiutaba | AE1: 30 Janauba | AF1: 31 Januaria | AG1: 32 JuizFora | AH1: 33 Lavras | AI1: 34 Manhuau | AJ1: 35 Mantena | AK1: 36 MontesClaros | AL1: 37 Muriae | AM1: 38 Nanuque | AN1: 39 Oliveira | AO1: 40 OuroPreto | AP1: 41 ParaMinas | AQ1: 42 Paracatu | AR1: 43 Passos | AS1: 44 PatosMinas | AT1: 45 Patrocinio | AU1: 46 Pecanha | AV1: 47 PedraAzul | AW1: 48 Pirapora | AX1: 49 Piui | AY1: 50 PocosCaldas | AZ1: 51 PonteNova | BA1: 52 PousoAlegre | BB1: 53 Salinas | BC1: 54 StaRitaSapuc | BD1: 55 SaoJoaoDRei | BE1: 56 SaoLoureno | BF1: 57 SaoSebParai | BG1: 58 SeteLagoas | BH1: 59 TeofOtoni | BI1: 60 TresMarias | BJ1: 61 Uba | BK1: 62 Uberaba | BL1: 63 Uberlandia | BM1: 64 Unai | BN1: 65 Varginha | BO1: 66 Vicosa | BP1: Total
A2: 1 Agropec | B2: {=ICMS_Micro!B2*xtot!B2} -> 8871880.1 | C2: {=ICMS_Micro!C2*xtot!C2} -> 45138049 | D2: {=ICMS_Micro!D2*xtot!D2} -> 12363332 | E2: {=ICMS_Micro!E2*xtot!E2} -> 7851908.1 | F2: {=ICMS_Micro!F2*xtot!F2} -> 7996180.7 | G2: {=ICMS_Micro!G2*xtot!G2} -> 65355948 | H2: {=ICMS_Micro!H2*xtot!H2} -> 14977110 | I2: {=ICMS_Micro!I2*xtot!I2} -> 69147473 | ... BO2: {=ICMS_Micro!BO2*xtot!BO2} -> 31161786 | BP2: {=SUM(B2:BO2)} -> 1.7230794e+09
A3: 2 Extrativa | B3: {=ICMS_Micro!B3*xtot!B3} -> 11858380 | C3: {=ICMS_Micro!C3*xtot!C3} -> 37565147 | D3: {=ICMS_Micro!D3*xtot!D3} -> 4856973.9 | E3: {=ICMS_Micro!E3*xtot!E3} -> 2111921.4 | F3: {=ICMS_Micro!F3*xtot!F3} -> 5151043.6 | G3: {=ICMS_Micro!G3*xtot!G3} -> 1.5352567e+08 | H3: {=ICMS_Micro!H3*xtot!H3} -> 21240602 | I3: {=ICMS_Micro!I3*xtot!I3} -> 5.3943719e+09 | ... BO3: {=ICMS_Micro!BO3*xtot!BO3} -> 9729812.6 | BP3: {=SUM(B3:BO3)} -> 1.0785057e+10
A4: 3 Industria | B4: {=ICMS_Micro!B4*xtot!B4} -> 1.1368542e+08 | C4: {=ICMS_Micro!C4*xtot!C4} -> 8.2658152e+08 | D4: {=ICMS_Micro!D4*xtot!D4} -> 1.4718378e+08 | E4: {=ICMS_Micro!E4*xtot!E4} -> 10609849 | F4: {=ICMS_Micro!F4*xtot!F4} -> 1.0635925e+08 | G4: {=ICMS_Micro!G4*xtot!G4} -> 3.8612218e+09 | H4: {=ICMS_Micro!H4*xtot!H4} -> 8.6748966e+08 | I4: {=ICMS_Micro!I4*xtot!I4} -> 2.2316403e+10 | ... BO4: {=ICMS_Micro!BO4*xtot!BO4} -> 2.5071958e+08 | BP4: {=SUM(B4:BO4)} -> 1.1690103e+11
A5: 6 Servico | B5: {=ICMS_Micro!B5*xtot!B5} -> 43044785 | C5: {=ICMS_Micro!C5*xtot!C5} -> 50917994 | D5: {=ICMS_Micro!D5*xtot!D5} -> 39160276 | E5: {=ICMS_Micro!E5*xtot!E5} -> 28958250 | F5: {=ICMS_Micro!F5*xtot!F5} -> 31933062 | G5: {=ICMS_Micro!G5*xtot!G5} -> 1.5933247e+08 | H5: {=ICMS_Micro!H5*xtot!H5} -> 51851946 | I5: {=ICMS_Micro!I5*xtot!I5} -> 1.9238687e+09 | ... BO5: {=ICMS_Micro!BO5*xtot!BO5} -> 29951451 | BP5: {=SUM(B5:BO5)} -> 8.7638103e+09
A6: 7 ComAtaVar | B6: {=ICMS_Micro!B6*xtot!B6} -> 3.4982522e+08 | C6: {=ICMS_Micro!C6*xtot!C6} -> 1.2118057e+09 | D6: {=ICMS_Micro!D6*xtot!D6} -> 3.4252949e+08 | E6: {=ICMS_Micro!E6*xtot!E6} -> 1.2380613e+08 | F6: {=ICMS_Micro!F6*xtot!F6} -> 1.8781966e+08 | G6: {=ICMS_Micro!G6*xtot!G6} -> 1.449095e+09 | H6: {=ICMS_Micro!H6*xtot!H6} -> 7.2999546e+08 | I6: {=ICMS_Micro!I6*xtot!I6} -> 3.4821045e+10 | ... BO6: {=ICMS_Micro!BO6*xtot!BO6} -> 6.9388911e+08 | BP6: {=SUM(B6:BO6)} -> 1.0810741e+11
A7: 8 TranspCarga | B7: {=ICMS_Micro!B7*xtot!B7} -> 4299131.5 | C7: {=ICMS_Micro!C7*xtot!C7} -> 30747616 | D7: {=ICMS_Micro!D7*xtot!D7} -> 213596.81 | E7: {=ICMS_Micro!E7*xtot!E7} -> -1692858 | F7: {=ICMS_Micro!F7*xtot!F7} -> 2425721 | G7: {=ICMS_Micro!G7*xtot!G7} -> 19141228 | H7: {=ICMS_Micro!H7*xtot!H7} -> 14123019 | I7: {=ICMS_Micro!I7*xtot!I7} -> 6.5664784e+08 | ... BO7: {=ICMS_Micro!BO7*xtot!BO7} -> 12882413 | BP7: {=SUM(B7:BO7)} -> 2.0400025e+09
BP9: {=SUM(BP2:BP7)} -> 2.4832039e+11
